Internal Server Error: /admin/myapp/laptop/add/
Traceback (most recent call last):
  File "C:\Users\Administrator\AppData\Local\Programs\Python\Python310\lib\site-packages\django\db\backends\utils.py", line 105, in _execute
    return self.cursor.execute(sql, params)
  File "C:\Users\Administrator\AppData\Local\Programs\Python\Python310\lib\site-packages\django\db\backends\sqlite3\base.py", line 329, in execute
    return super().execute(query, params)
sqlite3.OperationalError: no such table: myapp_laptop

The above exception was the direct cause of the following exception:

Traceback (most recent call last):
  File "C:\Users\Administrator\AppData\Local\Programs\Python\Python310\lib\site-packages\django\core\handlers\exception.py", line 55, in inner
    response = get_response(request)
  File "C:\Users\Administrator\AppData\Local\Programs\Python\Python310\lib\site-packages\django\core\handlers\base.py", line 197, in _get_response
    response = wrapped_callback(request, *callback_args, **callback_kwargs)
  File "C:\Users\Administrator\AppData\Local\Programs\Python\Python310\lib\site-packages\django\contrib\admin\options.py", line 716, in wrapper
    return self.admin_site.admin_view(view)(*args, **kwargs)
  File "C:\Users\Administrator\AppData\Local\Programs\Python\Python310\lib\site-packages\django\utils\decorators.py", line 188, in _view_wrapper
    result = _process_exception(request, e)
  File "C:\Users\Administrator\AppData\Local\Programs\Python\Python310\lib\site-packages\django\utils\decorators.py", line 186, in _view_wrapper
    response = view_func(request, *args, **kwargs)
  File "C:\Users\Administrator\AppData\Local\Programs\Python\Python310\lib\site-packages\django\views\decorators\cache.py", line 80, in _view_wrapper
    response = view_func(request, *args, **kwargs)
  File "C:\Users\Administrator\AppData\Local\Programs\Python\Python310\lib\site-packages\django\contrib\admin\sites.py", line 240, in inner
    return view(request, *args, **kwargs)
  File "C:\Users\Administrator\AppData\Local\Programs\Python\Python310\lib\site-packages\django\contrib\admin\options.py", line 1945, in add_view
    return self.changeform_view(request, None, form_url, extra_context)
  File "C:\Users\Administrator\AppData\Local\Programs\Python\Python310\lib\site-packages\django\utils\decorators.py", line 48, in _wrapper
    return bound_method(*args, **kwargs)
  File "C:\Users\Administrator\AppData\Local\Programs\Python\Python310\lib\site-packages\django\utils\decorators.py", line 188, in _view_wrapper
    result = _process_exception(request, e)
  File "C:\Users\Administrator\AppData\Local\Programs\Python\Python310\lib\site-packages\django\utils\decorators.py", line 186, in _view_wrapper
    response = view_func(request, *args, **kwargs)
  File "C:\Users\Administrator\AppData\Local\Programs\Python\Python310\lib\site-packages\django\contrib\admin\options.py", line 1804, in changeform_view
    return self._changeform_view(request, object_id, form_url, extra_context)
  File "C:\Users\Administrator\AppData\Local\Programs\Python\Python310\lib\site-packages\django\contrib\admin\options.py", line 1855, in _changeform_view
    self.save_model(request, new_object, form, not add)
  File "C:\Users\Administrator\AppData\Local\Programs\Python\Python310\lib\site-packages\django\contrib\admin\options.py", line 1259, in save_model
    obj.save()
  File "C:\Users\Administrator\AppData\Local\Programs\Python\Python310\lib\site-packages\django\db\models\base.py", line 822, in save
    self.save_base(
  File "C:\Users\Administrator\AppData\Local\Programs\Python\Python310\lib\site-packages\django\db\models\base.py", line 909, in save_base
    updated = self._save_table(
  File "C:\Users\Administrator\AppData\Local\Programs\Python\Python310\lib\site-packages\django\db\models\base.py", line 1071, in _save_table
    results = self._do_insert(
  File "C:\Users\Administrator\AppData\Local\Programs\Python\Python310\lib\site-packages\django\db\models\base.py", line 1112, in _do_insert
    return manager._insert(
  File "C:\Users\Administrator\AppData\Local\Programs\Python\Python310\lib\site-packages\django\db\models\manager.py", line 87, in manager_method
    return getattr(self.get_queryset(), name)(*args, **kwargs)
  File "C:\Users\Administrator\AppData\Local\Programs\Python\Python310\lib\site-packages\django\db\models\query.py", line 1847, in _insert
    return query.get_compiler(using=using).execute_sql(returning_fields)
  File "C:\Users\Administrator\AppData\Local\Programs\Python\Python310\lib\site-packages\django\db\models\sql\compiler.py", line 1823, in execute_sql
    cursor.execute(sql, params)
  File "C:\Users\Administrator\AppData\Local\Programs\Python\Python310\lib\site-packages\django\db\backends\utils.py", line 79, in execute
    return self._execute_with_wrappers(
  File "C:\Users\Administrator\AppData\Local\Programs\Python\Python310\lib\site-packages\django\db\backends\utils.py", line 92, in _execute_with_wrappers
    return executor(sql, params, many, context)
  File "C:\Users\Administrator\AppData\Local\Programs\Python\Python310\lib\site-packages\django\db\backends\utils.py", line 100, in _execute
    with self.db.wrap_database_errors:
  File "C:\Users\Administrator\AppData\Local\Programs\Python\Python310\lib\site-packages\django\db\utils.py", line 91, in __exit__
    raise dj_exc_value.with_traceback(traceback) from exc_value
  File "C:\Users\Administrator\AppData\Local\Programs\Python\Python310\lib\site-packages\django\db\backends\utils.py", line 105, in _execute
    return self.cursor.execute(sql, params)
  File "C:\Users\Administrator\AppData\Local\Programs\Python\Python310\lib\site-packages\django\db\backends\sqlite3\base.py", line 329, in execute
    return super().execute(query, params)
django.db.utils.OperationalError: no such table: myapp_laptop
"POST /admin/myapp/laptop/add/ HTTP/1.1" 500 145
Internal Server Error: /admin/myapp/laptop/add/
Traceback (most recent call last):
  File "C:\Users\Administrator\AppData\Local\Programs\Python\Python310\lib\site-packages\django\db\backends\utils.py", line 105, in _execute
    return self.cursor.execute(sql, params)
  File "C:\Users\Administrator\AppData\Local\Programs\Python\Python310\lib\site-packages\django\db\backends\sqlite3\base.py", line 329, in execute
    return super().execute(query, params)
sqlite3.OperationalError: no such table: myapp_laptop

The above exception was the direct cause of the following exception:

Traceback (most recent call last):
  File "C:\Users\Administrator\AppData\Local\Programs\Python\Python310\lib\site-packages\django\core\handlers\exception.py", line 55, in inner
    response = get_response(request)
  File "C:\Users\Administrator\AppData\Local\Programs\Python\Python310\lib\site-packages\django\core\handlers\base.py", line 197, in _get_response
    response = wrapped_callback(request, *callback_args, **callback_kwargs)
  File "C:\Users\Administrator\AppData\Local\Programs\Python\Python310\lib\site-packages\django\contrib\admin\options.py", line 716, in wrapper
    return self.admin_site.admin_view(view)(*args, **kwargs)
  File "C:\Users\Administrator\AppData\Local\Programs\Python\Python310\lib\site-packages\django\utils\decorators.py", line 188, in _view_wrapper
    result = _process_exception(request, e)
  File "C:\Users\Administrator\AppData\Local\Programs\Python\Python310\lib\site-packages\django\utils\decorators.py", line 186, in _view_wrapper
    response = view_func(request, *args, **kwargs)
  File "C:\Users\Administrator\AppData\Local\Programs\Python\Python310\lib\site-packages\django\views\decorators\cache.py", line 80, in _view_wrapper
    response = view_func(request, *args, **kwargs)
  File "C:\Users\Administrator\AppData\Local\Programs\Python\Python310\lib\site-packages\django\contrib\admin\sites.py", line 240, in inner
    return view(request, *args, **kwargs)
  File "C:\Users\Administrator\AppData\Local\Programs\Python\Python310\lib\site-packages\django\contrib\admin\options.py", line 1945, in add_view
    return self.changeform_view(request, None, form_url, extra_context)
  File "C:\Users\Administrator\AppData\Local\Programs\Python\Python310\lib\site-packages\django\utils\decorators.py", line 48, in _wrapper
    return bound_method(*args, **kwargs)
  File "C:\Users\Administrator\AppData\Local\Programs\Python\Python310\lib\site-packages\django\utils\decorators.py", line 188, in _view_wrapper
    result = _process_exception(request, e)
  File "C:\Users\Administrator\AppData\Local\Programs\Python\Python310\lib\site-packages\django\utils\decorators.py", line 186, in _view_wrapper
    response = view_func(request, *args, **kwargs)
  File "C:\Users\Administrator\AppData\Local\Programs\Python\Python310\lib\site-packages\django\contrib\admin\options.py", line 1804, in changeform_view
    return self._changeform_view(request, object_id, form_url, extra_context)
  File "C:\Users\Administrator\AppData\Local\Programs\Python\Python310\lib\site-packages\django\contrib\admin\options.py", line 1855, in _changeform_view
    self.save_model(request, new_object, form, not add)
  File "C:\Users\Administrator\AppData\Local\Programs\Python\Python310\lib\site-packages\django\contrib\admin\options.py", line 1259, in save_model
    obj.save()
  File "C:\Users\Administrator\AppData\Local\Programs\Python\Python310\lib\site-packages\django\db\models\base.py", line 822, in save
    self.save_base(
  File "C:\Users\Administrator\AppData\Local\Programs\Python\Python310\lib\site-packages\django\db\models\base.py", line 909, in save_base
    updated = self._save_table(
  File "C:\Users\Administrator\AppData\Local\Programs\Python\Python310\lib\site-packages\django\db\models\base.py", line 1071, in _save_table
    results = self._do_insert(
  File "C:\Users\Administrator\AppData\Local\Programs\Python\Python310\lib\site-packages\django\db\models\base.py", line 1112, in _do_insert
    return manager._insert(
  File "C:\Users\Administrator\AppData\Local\Programs\Python\Python310\lib\site-packages\django\db\models\manager.py", line 87, in manager_method
    return getattr(self.get_queryset(), name)(*args, **kwargs)
  File "C:\Users\Administrator\AppData\Local\Programs\Python\Python310\lib\site-packages\django\db\models\query.py", line 1847, in _insert
    return query.get_compiler(using=using).execute_sql(returning_fields)
  File "C:\Users\Administrator\AppData\Local\Programs\Python\Python310\lib\site-packages\django\db\models\sql\compiler.py", line 1823, in execute_sql
    cursor.execute(sql, params)
  File "C:\Users\Administrator\AppData\Local\Programs\Python\Python310\lib\site-packages\django\db\backends\utils.py", line 79, in execute
    return self._execute_with_wrappers(
  File "C:\Users\Administrator\AppData\Local\Programs\Python\Python310\lib\site-packages\django\db\backends\utils.py", line 92, in _execute_with_wrappers
    return executor(sql, params, many, context)
  File "C:\Users\Administrator\AppData\Local\Programs\Python\Python310\lib\site-packages\django\db\backends\utils.py", line 100, in _execute
    with self.db.wrap_database_errors:
  File "C:\Users\Administrator\AppData\Local\Programs\Python\Python310\lib\site-packages\django\db\utils.py", line 91, in __exit__
    raise dj_exc_value.with_traceback(traceback) from exc_value
  File "C:\Users\Administrator\AppData\Local\Programs\Python\Python310\lib\site-packages\django\db\backends\utils.py", line 105, in _execute
    return self.cursor.execute(sql, params)
  File "C:\Users\Administrator\AppData\Local\Programs\Python\Python310\lib\site-packages\django\db\backends\sqlite3\base.py", line 329, in execute
    return super().execute(query, params)
django.db.utils.OperationalError: no such table: myapp_laptop
"POST /admin/myapp/laptop/add/ HTTP/1.1" 500 145
Internal Server Error: /admin/myapp/laptop/add/
Traceback (most recent call last):
  File "C:\Users\Administrator\AppData\Local\Programs\Python\Python310\lib\site-packages\django\db\backends\utils.py", line 105, in _execute
    return self.cursor.execute(sql, params)
  File "C:\Users\Administrator\AppData\Local\Programs\Python\Python310\lib\site-packages\django\db\backends\sqlite3\base.py", line 329, in execute
    return super().execute(query, params)
sqlite3.OperationalError: no such table: myapp_laptop

The above exception was the direct cause of the following exception:

Traceback (most recent call last):
  File "C:\Users\Administrator\AppData\Local\Programs\Python\Python310\lib\site-packages\django\core\handlers\exception.py", line 55, in inner
    response = get_response(request)
  File "C:\Users\Administrator\AppData\Local\Programs\Python\Python310\lib\site-packages\django\core\handlers\base.py", line 197, in _get_response
    response = wrapped_callback(request, *callback_args, **callback_kwargs)
  File "C:\Users\Administrator\AppData\Local\Programs\Python\Python310\lib\site-packages\django\contrib\admin\options.py", line 716, in wrapper
    return self.admin_site.admin_view(view)(*args, **kwargs)
  File "C:\Users\Administrator\AppData\Local\Programs\Python\Python310\lib\site-packages\django\utils\decorators.py", line 188, in _view_wrapper
    result = _process_exception(request, e)
  File "C:\Users\Administrator\AppData\Local\Programs\Python\Python310\lib\site-packages\django\utils\decorators.py", line 186, in _view_wrapper
    response = view_func(request, *args, **kwargs)
  File "C:\Users\Administrator\AppData\Local\Programs\Python\Python310\lib\site-packages\django\views\decorators\cache.py", line 80, in _view_wrapper
    response = view_func(request, *args, **kwargs)
  File "C:\Users\Administrator\AppData\Local\Programs\Python\Python310\lib\site-packages\django\contrib\admin\sites.py", line 240, in inner
    return view(request, *args, **kwargs)
  File "C:\Users\Administrator\AppData\Local\Programs\Python\Python310\lib\site-packages\django\contrib\admin\options.py", line 1945, in add_view
    return self.changeform_view(request, None, form_url, extra_context)
  File "C:\Users\Administrator\AppData\Local\Programs\Python\Python310\lib\site-packages\django\utils\decorators.py", line 48, in _wrapper
    return bound_method(*args, **kwargs)
  File "C:\Users\Administrator\AppData\Local\Programs\Python\Python310\lib\site-packages\django\utils\decorators.py", line 188, in _view_wrapper
    result = _process_exception(request, e)
  File "C:\Users\Administrator\AppData\Local\Programs\Python\Python310\lib\site-packages\django\utils\decorators.py", line 186, in _view_wrapper
    response = view_func(request, *args, **kwargs)
  File "C:\Users\Administrator\AppData\Local\Programs\Python\Python310\lib\site-packages\django\contrib\admin\options.py", line 1804, in changeform_view
    return self._changeform_view(request, object_id, form_url, extra_context)
  File "C:\Users\Administrator\AppData\Local\Programs\Python\Python310\lib\site-packages\django\contrib\admin\options.py", line 1855, in _changeform_view
    self.save_model(request, new_object, form, not add)
  File "C:\Users\Administrator\AppData\Local\Programs\Python\Python310\lib\site-packages\django\contrib\admin\options.py", line 1259, in save_model
    obj.save()
  File "C:\Users\Administrator\AppData\Local\Programs\Python\Python310\lib\site-packages\django\db\models\base.py", line 822, in save
    self.save_base(
  File "C:\Users\Administrator\AppData\Local\Programs\Python\Python310\lib\site-packages\django\db\models\base.py", line 909, in save_base
    updated = self._save_table(
  File "C:\Users\Administrator\AppData\Local\Programs\Python\Python310\lib\site-packages\django\db\models\base.py", line 1071, in _save_table
    results = self._do_insert(
  File "C:\Users\Administrator\AppData\Local\Programs\Python\Python310\lib\site-packages\django\db\models\base.py", line 1112, in _do_insert
    return manager._insert(
  File "C:\Users\Administrator\AppData\Local\Programs\Python\Python310\lib\site-packages\django\db\models\manager.py", line 87, in manager_method
    return getattr(self.get_queryset(), name)(*args, **kwargs)
  File "C:\Users\Administrator\AppData\Local\Programs\Python\Python310\lib\site-packages\django\db\models\query.py", line 1847, in _insert
    return query.get_compiler(using=using).execute_sql(returning_fields)
  File "C:\Users\Administrator\AppData\Local\Programs\Python\Python310\lib\site-packages\django\db\models\sql\compiler.py", line 1823, in execute_sql
    cursor.execute(sql, params)
  File "C:\Users\Administrator\AppData\Local\Programs\Python\Python310\lib\site-packages\django\db\backends\utils.py", line 79, in execute
    return self._execute_with_wrappers(
  File "C:\Users\Administrator\AppData\Local\Programs\Python\Python310\lib\site-packages\django\db\backends\utils.py", line 92, in _execute_with_wrappers
    return executor(sql, params, many, context)
  File "C:\Users\Administrator\AppData\Local\Programs\Python\Python310\lib\site-packages\django\db\backends\utils.py", line 100, in _execute
    with self.db.wrap_database_errors:
  File "C:\Users\Administrator\AppData\Local\Programs\Python\Python310\lib\site-packages\django\db\utils.py", line 91, in __exit__
    raise dj_exc_value.with_traceback(traceback) from exc_value
  File "C:\Users\Administrator\AppData\Local\Programs\Python\Python310\lib\site-packages\django\db\backends\utils.py", line 105, in _execute
    return self.cursor.execute(sql, params)
  File "C:\Users\Administrator\AppData\Local\Programs\Python\Python310\lib\site-packages\django\db\backends\sqlite3\base.py", line 329, in execute
    return super().execute(query, params)
django.db.utils.OperationalError: no such table: myapp_laptop
"POST /admin/myapp/laptop/add/ HTTP/1.1" 500 145
Internal Server Error: /admin/myapp/laptop/add/
Traceback (most recent call last):
  File "C:\Users\Administrator\AppData\Local\Programs\Python\Python310\lib\site-packages\django\db\backends\utils.py", line 105, in _execute
    return self.cursor.execute(sql, params)
  File "C:\Users\Administrator\AppData\Local\Programs\Python\Python310\lib\site-packages\django\db\backends\sqlite3\base.py", line 329, in execute
    return super().execute(query, params)
sqlite3.OperationalError: no such table: myapp_laptop

The above exception was the direct cause of the following exception:

Traceback (most recent call last):
  File "C:\Users\Administrator\AppData\Local\Programs\Python\Python310\lib\site-packages\django\core\handlers\exception.py", line 55, in inner
    response = get_response(request)
  File "C:\Users\Administrator\AppData\Local\Programs\Python\Python310\lib\site-packages\django\core\handlers\base.py", line 197, in _get_response
    response = wrapped_callback(request, *callback_args, **callback_kwargs)
  File "C:\Users\Administrator\AppData\Local\Programs\Python\Python310\lib\site-packages\django\contrib\admin\options.py", line 716, in wrapper
    return self.admin_site.admin_view(view)(*args, **kwargs)
  File "C:\Users\Administrator\AppData\Local\Programs\Python\Python310\lib\site-packages\django\utils\decorators.py", line 188, in _view_wrapper
    result = _process_exception(request, e)
  File "C:\Users\Administrator\AppData\Local\Programs\Python\Python310\lib\site-packages\django\utils\decorators.py", line 186, in _view_wrapper
    response = view_func(request, *args, **kwargs)
  File "C:\Users\Administrator\AppData\Local\Programs\Python\Python310\lib\site-packages\django\views\decorators\cache.py", line 80, in _view_wrapper
    response = view_func(request, *args, **kwargs)
  File "C:\Users\Administrator\AppData\Local\Programs\Python\Python310\lib\site-packages\django\contrib\admin\sites.py", line 240, in inner
    return view(request, *args, **kwargs)
  File "C:\Users\Administrator\AppData\Local\Programs\Python\Python310\lib\site-packages\django\contrib\admin\options.py", line 1945, in add_view
    return self.changeform_view(request, None, form_url, extra_context)
  File "C:\Users\Administrator\AppData\Local\Programs\Python\Python310\lib\site-packages\django\utils\decorators.py", line 48, in _wrapper
    return bound_method(*args, **kwargs)
  File "C:\Users\Administrator\AppData\Local\Programs\Python\Python310\lib\site-packages\django\utils\decorators.py", line 188, in _view_wrapper
    result = _process_exception(request, e)
  File "C:\Users\Administrator\AppData\Local\Programs\Python\Python310\lib\site-packages\django\utils\decorators.py", line 186, in _view_wrapper
    response = view_func(request, *args, **kwargs)
  File "C:\Users\Administrator\AppData\Local\Programs\Python\Python310\lib\site-packages\django\contrib\admin\options.py", line 1804, in changeform_view
    return self._changeform_view(request, object_id, form_url, extra_context)
  File "C:\Users\Administrator\AppData\Local\Programs\Python\Python310\lib\site-packages\django\contrib\admin\options.py", line 1855, in _changeform_view
    self.save_model(request, new_object, form, not add)
  File "C:\Users\Administrator\AppData\Local\Programs\Python\Python310\lib\site-packages\django\contrib\admin\options.py", line 1259, in save_model
    obj.save()
  File "C:\Users\Administrator\AppData\Local\Programs\Python\Python310\lib\site-packages\django\db\models\base.py", line 822, in save
    self.save_base(
  File "C:\Users\Administrator\AppData\Local\Programs\Python\Python310\lib\site-packages\django\db\models\base.py", line 909, in save_base
    updated = self._save_table(
  File "C:\Users\Administrator\AppData\Local\Programs\Python\Python310\lib\site-packages\django\db\models\base.py", line 1071, in _save_table
    results = self._do_insert(
  File "C:\Users\Administrator\AppData\Local\Programs\Python\Python310\lib\site-packages\django\db\models\base.py", line 1112, in _do_insert
    return manager._insert(
  File "C:\Users\Administrator\AppData\Local\Programs\Python\Python310\lib\site-packages\django\db\models\manager.py", line 87, in manager_method
    return getattr(self.get_queryset(), name)(*args, **kwargs)
  File "C:\Users\Administrator\AppData\Local\Programs\Python\Python310\lib\site-packages\django\db\models\query.py", line 1847, in _insert
    return query.get_compiler(using=using).execute_sql(returning_fields)
  File "C:\Users\Administrator\AppData\Local\Programs\Python\Python310\lib\site-packages\django\db\models\sql\compiler.py", line 1823, in execute_sql
    cursor.execute(sql, params)
  File "C:\Users\Administrator\AppData\Local\Programs\Python\Python310\lib\site-packages\django\db\backends\utils.py", line 79, in execute
    return self._execute_with_wrappers(
  File "C:\Users\Administrator\AppData\Local\Programs\Python\Python310\lib\site-packages\django\db\backends\utils.py", line 92, in _execute_with_wrappers
    return executor(sql, params, many, context)
  File "C:\Users\Administrator\AppData\Local\Programs\Python\Python310\lib\site-packages\django\db\backends\utils.py", line 100, in _execute
    with self.db.wrap_database_errors:
  File "C:\Users\Administrator\AppData\Local\Programs\Python\Python310\lib\site-packages\django\db\utils.py", line 91, in __exit__
    raise dj_exc_value.with_traceback(traceback) from exc_value
  File "C:\Users\Administrator\AppData\Local\Programs\Python\Python310\lib\site-packages\django\db\backends\utils.py", line 105, in _execute
    return self.cursor.execute(sql, params)
  File "C:\Users\Administrator\AppData\Local\Programs\Python\Python310\lib\site-packages\django\db\backends\sqlite3\base.py", line 329, in execute
    return super().execute(query, params)
django.db.utils.OperationalError: no such table: myapp_laptop
"POST /admin/myapp/laptop/add/ HTTP/1.1" 500 145
Internal Server Error: /admin/myapp/laptop/add/
Traceback (most recent call last):
  File "C:\Users\Administrator\AppData\Local\Programs\Python\Python310\lib\site-packages\django\db\backends\utils.py", line 105, in _execute
    return self.cursor.execute(sql, params)
  File "C:\Users\Administrator\AppData\Local\Programs\Python\Python310\lib\site-packages\django\db\backends\sqlite3\base.py", line 329, in execute
    return super().execute(query, params)
sqlite3.OperationalError: no such table: myapp_laptop

The above exception was the direct cause of the following exception:

Traceback (most recent call last):
  File "C:\Users\Administrator\AppData\Local\Programs\Python\Python310\lib\site-packages\django\core\handlers\exception.py", line 55, in inner
    response = get_response(request)
  File "C:\Users\Administrator\AppData\Local\Programs\Python\Python310\lib\site-packages\django\core\handlers\base.py", line 197, in _get_response
    response = wrapped_callback(request, *callback_args, **callback_kwargs)
  File "C:\Users\Administrator\AppData\Local\Programs\Python\Python310\lib\site-packages\django\contrib\admin\options.py", line 716, in wrapper
    return self.admin_site.admin_view(view)(*args, **kwargs)
  File "C:\Users\Administrator\AppData\Local\Programs\Python\Python310\lib\site-packages\django\utils\decorators.py", line 188, in _view_wrapper
    result = _process_exception(request, e)
  File "C:\Users\Administrator\AppData\Local\Programs\Python\Python310\lib\site-packages\django\utils\decorators.py", line 186, in _view_wrapper
    response = view_func(request, *args, **kwargs)
  File "C:\Users\Administrator\AppData\Local\Programs\Python\Python310\lib\site-packages\django\views\decorators\cache.py", line 80, in _view_wrapper
    response = view_func(request, *args, **kwargs)
  File "C:\Users\Administrator\AppData\Local\Programs\Python\Python310\lib\site-packages\django\contrib\admin\sites.py", line 240, in inner
    return view(request, *args, **kwargs)
  File "C:\Users\Administrator\AppData\Local\Programs\Python\Python310\lib\site-packages\django\contrib\admin\options.py", line 1945, in add_view
    return self.changeform_view(request, None, form_url, extra_context)
  File "C:\Users\Administrator\AppData\Local\Programs\Python\Python310\lib\site-packages\django\utils\decorators.py", line 48, in _wrapper
    return bound_method(*args, **kwargs)
  File "C:\Users\Administrator\AppData\Local\Programs\Python\Python310\lib\site-packages\django\utils\decorators.py", line 188, in _view_wrapper
    result = _process_exception(request, e)
  File "C:\Users\Administrator\AppData\Local\Programs\Python\Python310\lib\site-packages\django\utils\decorators.py", line 186, in _view_wrapper
    response = view_func(request, *args, **kwargs)
  File "C:\Users\Administrator\AppData\Local\Programs\Python\Python310\lib\site-packages\django\contrib\admin\options.py", line 1804, in changeform_view
    return self._changeform_view(request, object_id, form_url, extra_context)
  File "C:\Users\Administrator\AppData\Local\Programs\Python\Python310\lib\site-packages\django\contrib\admin\options.py", line 1855, in _changeform_view
    self.save_model(request, new_object, form, not add)
  File "C:\Users\Administrator\AppData\Local\Programs\Python\Python310\lib\site-packages\django\contrib\admin\options.py", line 1259, in save_model
    obj.save()
  File "C:\Users\Administrator\AppData\Local\Programs\Python\Python310\lib\site-packages\django\db\models\base.py", line 822, in save
    self.save_base(
  File "C:\Users\Administrator\AppData\Local\Programs\Python\Python310\lib\site-packages\django\db\models\base.py", line 909, in save_base
    updated = self._save_table(
  File "C:\Users\Administrator\AppData\Local\Programs\Python\Python310\lib\site-packages\django\db\models\base.py", line 1071, in _save_table
    results = self._do_insert(
  File "C:\Users\Administrator\AppData\Local\Programs\Python\Python310\lib\site-packages\django\db\models\base.py", line 1112, in _do_insert
    return manager._insert(
  File "C:\Users\Administrator\AppData\Local\Programs\Python\Python310\lib\site-packages\django\db\models\manager.py", line 87, in manager_method
    return getattr(self.get_queryset(), name)(*args, **kwargs)
  File "C:\Users\Administrator\AppData\Local\Programs\Python\Python310\lib\site-packages\django\db\models\query.py", line 1847, in _insert
    return query.get_compiler(using=using).execute_sql(returning_fields)
  File "C:\Users\Administrator\AppData\Local\Programs\Python\Python310\lib\site-packages\django\db\models\sql\compiler.py", line 1823, in execute_sql
    cursor.execute(sql, params)
  File "C:\Users\Administrator\AppData\Local\Programs\Python\Python310\lib\site-packages\django\db\backends\utils.py", line 79, in execute
    return self._execute_with_wrappers(
  File "C:\Users\Administrator\AppData\Local\Programs\Python\Python310\lib\site-packages\django\db\backends\utils.py", line 92, in _execute_with_wrappers
    return executor(sql, params, many, context)
  File "C:\Users\Administrator\AppData\Local\Programs\Python\Python310\lib\site-packages\django\db\backends\utils.py", line 100, in _execute
    with self.db.wrap_database_errors:
  File "C:\Users\Administrator\AppData\Local\Programs\Python\Python310\lib\site-packages\django\db\utils.py", line 91, in __exit__
    raise dj_exc_value.with_traceback(traceback) from exc_value
  File "C:\Users\Administrator\AppData\Local\Programs\Python\Python310\lib\site-packages\django\db\backends\utils.py", line 105, in _execute
    return self.cursor.execute(sql, params)
  File "C:\Users\Administrator\AppData\Local\Programs\Python\Python310\lib\site-packages\django\db\backends\sqlite3\base.py", line 329, in execute
    return super().execute(query, params)
django.db.utils.OperationalError: no such table: myapp_laptop
"POST /admin/myapp/laptop/add/ HTTP/1.1" 500 145
Internal Server Error: /admin/myapp/laptop/add/
Traceback (most recent call last):
  File "C:\Users\Administrator\AppData\Local\Programs\Python\Python310\lib\site-packages\django\db\backends\utils.py", line 105, in _execute
    return self.cursor.execute(sql, params)
  File "C:\Users\Administrator\AppData\Local\Programs\Python\Python310\lib\site-packages\django\db\backends\sqlite3\base.py", line 329, in execute
    return super().execute(query, params)
sqlite3.OperationalError: no such table: myapp_laptop

The above exception was the direct cause of the following exception:

Traceback (most recent call last):
  File "C:\Users\Administrator\AppData\Local\Programs\Python\Python310\lib\site-packages\django\core\handlers\exception.py", line 55, in inner
    response = get_response(request)
  File "C:\Users\Administrator\AppData\Local\Programs\Python\Python310\lib\site-packages\django\core\handlers\base.py", line 197, in _get_response
    response = wrapped_callback(request, *callback_args, **callback_kwargs)
  File "C:\Users\Administrator\AppData\Local\Programs\Python\Python310\lib\site-packages\django\contrib\admin\options.py", line 716, in wrapper
    return self.admin_site.admin_view(view)(*args, **kwargs)
  File "C:\Users\Administrator\AppData\Local\Programs\Python\Python310\lib\site-packages\django\utils\decorators.py", line 188, in _view_wrapper
    result = _process_exception(request, e)
  File "C:\Users\Administrator\AppData\Local\Programs\Python\Python310\lib\site-packages\django\utils\decorators.py", line 186, in _view_wrapper
    response = view_func(request, *args, **kwargs)
  File "C:\Users\Administrator\AppData\Local\Programs\Python\Python310\lib\site-packages\django\views\decorators\cache.py", line 80, in _view_wrapper
    response = view_func(request, *args, **kwargs)
  File "C:\Users\Administrator\AppData\Local\Programs\Python\Python310\lib\site-packages\django\contrib\admin\sites.py", line 240, in inner
    return view(request, *args, **kwargs)
  File "C:\Users\Administrator\AppData\Local\Programs\Python\Python310\lib\site-packages\django\contrib\admin\options.py", line 1945, in add_view
    return self.changeform_view(request, None, form_url, extra_context)
  File "C:\Users\Administrator\AppData\Local\Programs\Python\Python310\lib\site-packages\django\utils\decorators.py", line 48, in _wrapper
    return bound_method(*args, **kwargs)
  File "C:\Users\Administrator\AppData\Local\Programs\Python\Python310\lib\site-packages\django\utils\decorators.py", line 188, in _view_wrapper
    result = _process_exception(request, e)
  File "C:\Users\Administrator\AppData\Local\Programs\Python\Python310\lib\site-packages\django\utils\decorators.py", line 186, in _view_wrapper
    response = view_func(request, *args, **kwargs)
  File "C:\Users\Administrator\AppData\Local\Programs\Python\Python310\lib\site-packages\django\contrib\admin\options.py", line 1804, in changeform_view
    return self._changeform_view(request, object_id, form_url, extra_context)
  File "C:\Users\Administrator\AppData\Local\Programs\Python\Python310\lib\site-packages\django\contrib\admin\options.py", line 1855, in _changeform_view
    self.save_model(request, new_object, form, not add)
  File "C:\Users\Administrator\AppData\Local\Programs\Python\Python310\lib\site-packages\django\contrib\admin\options.py", line 1259, in save_model
    obj.save()
  File "C:\Users\Administrator\AppData\Local\Programs\Python\Python310\lib\site-packages\django\db\models\base.py", line 822, in save
    self.save_base(
  File "C:\Users\Administrator\AppData\Local\Programs\Python\Python310\lib\site-packages\django\db\models\base.py", line 909, in save_base
    updated = self._save_table(
  File "C:\Users\Administrator\AppData\Local\Programs\Python\Python310\lib\site-packages\django\db\models\base.py", line 1071, in _save_table
    results = self._do_insert(
  File "C:\Users\Administrator\AppData\Local\Programs\Python\Python310\lib\site-packages\django\db\models\base.py", line 1112, in _do_insert
    return manager._insert(
  File "C:\Users\Administrator\AppData\Local\Programs\Python\Python310\lib\site-packages\django\db\models\manager.py", line 87, in manager_method
    return getattr(self.get_queryset(), name)(*args, **kwargs)
  File "C:\Users\Administrator\AppData\Local\Programs\Python\Python310\lib\site-packages\django\db\models\query.py", line 1847, in _insert
    return query.get_compiler(using=using).execute_sql(returning_fields)
  File "C:\Users\Administrator\AppData\Local\Programs\Python\Python310\lib\site-packages\django\db\models\sql\compiler.py", line 1823, in execute_sql
    cursor.execute(sql, params)
  File "C:\Users\Administrator\AppData\Local\Programs\Python\Python310\lib\site-packages\django\db\backends\utils.py", line 79, in execute
    return self._execute_with_wrappers(
  File "C:\Users\Administrator\AppData\Local\Programs\Python\Python310\lib\site-packages\django\db\backends\utils.py", line 92, in _execute_with_wrappers
    return executor(sql, params, many, context)
  File "C:\Users\Administrator\AppData\Local\Programs\Python\Python310\lib\site-packages\django\db\backends\utils.py", line 100, in _execute
    with self.db.wrap_database_errors:
  File "C:\Users\Administrator\AppData\Local\Programs\Python\Python310\lib\site-packages\django\db\utils.py", line 91, in __exit__
    raise dj_exc_value.with_traceback(traceback) from exc_value
  File "C:\Users\Administrator\AppData\Local\Programs\Python\Python310\lib\site-packages\django\db\backends\utils.py", line 105, in _execute
    return self.cursor.execute(sql, params)
  File "C:\Users\Administrator\AppData\Local\Programs\Python\Python310\lib\site-packages\django\db\backends\sqlite3\base.py", line 329, in execute
    return super().execute(query, params)
django.db.utils.OperationalError: no such table: myapp_laptop
"POST /admin/myapp/laptop/add/ HTTP/1.1" 500 145
Internal Server Error: /admin/myapp/laptop/
Traceback (most recent call last):
  File "C:\Users\Administrator\AppData\Local\Programs\Python\Python310\lib\site-packages\django\db\backends\utils.py", line 105, in _execute
    return self.cursor.execute(sql, params)
  File "C:\Users\Administrator\AppData\Local\Programs\Python\Python310\lib\site-packages\django\db\backends\sqlite3\base.py", line 329, in execute
    return super().execute(query, params)
sqlite3.OperationalError: no such table: myapp_laptop

The above exception was the direct cause of the following exception:

Traceback (most recent call last):
  File "C:\Users\Administrator\AppData\Local\Programs\Python\Python310\lib\site-packages\django\core\handlers\exception.py", line 55, in inner
    response = get_response(request)
  File "C:\Users\Administrator\AppData\Local\Programs\Python\Python310\lib\site-packages\django\core\handlers\base.py", line 197, in _get_response
    response = wrapped_callback(request, *callback_args, **callback_kwargs)
  File "C:\Users\Administrator\AppData\Local\Programs\Python\Python310\lib\site-packages\django\contrib\admin\options.py", line 716, in wrapper
    return self.admin_site.admin_view(view)(*args, **kwargs)
  File "C:\Users\Administrator\AppData\Local\Programs\Python\Python310\lib\site-packages\django\utils\decorators.py", line 188, in _view_wrapper
    result = _process_exception(request, e)
  File "C:\Users\Administrator\AppData\Local\Programs\Python\Python310\lib\site-packages\django\utils\decorators.py", line 186, in _view_wrapper
    response = view_func(request, *args, **kwargs)
  File "C:\Users\Administrator\AppData\Local\Programs\Python\Python310\lib\site-packages\django\views\decorators\cache.py", line 80, in _view_wrapper
    response = view_func(request, *args, **kwargs)
  File "C:\Users\Administrator\AppData\Local\Programs\Python\Python310\lib\site-packages\django\contrib\admin\sites.py", line 240, in inner
    return view(request, *args, **kwargs)
  File "C:\Users\Administrator\AppData\Local\Programs\Python\Python310\lib\site-packages\django\utils\decorators.py", line 48, in _wrapper
    return bound_method(*args, **kwargs)
  File "C:\Users\Administrator\AppData\Local\Programs\Python\Python310\lib\site-packages\django\utils\decorators.py", line 188, in _view_wrapper
    result = _process_exception(request, e)
  File "C:\Users\Administrator\AppData\Local\Programs\Python\Python310\lib\site-packages\django\utils\decorators.py", line 186, in _view_wrapper
    response = view_func(request, *args, **kwargs)
  File "C:\Users\Administrator\AppData\Local\Programs\Python\Python310\lib\site-packages\django\contrib\admin\options.py", line 1985, in changelist_view
    cl = self.get_changelist_instance(request)
  File "C:\Users\Administrator\AppData\Local\Programs\Python\Python310\lib\site-packages\django\contrib\admin\options.py", line 864, in get_changelist_instance
    return ChangeList(
  File "C:\Users\Administrator\AppData\Local\Programs\Python\Python310\lib\site-packages\django\contrib\admin\views\main.py", line 145, in __init__
    self.get_results(request)
  File "C:\Users\Administrator\AppData\Local\Programs\Python\Python310\lib\site-packages\django\contrib\admin\views\main.py", line 312, in get_results
    result_count = paginator.count
  File "C:\Users\Administrator\AppData\Local\Programs\Python\Python310\lib\site-packages\django\utils\functional.py", line 47, in __get__
    res = instance.__dict__[self.name] = self.func(instance)
  File "C:\Users\Administrator\AppData\Local\Programs\Python\Python310\lib\site-packages\django\core\paginator.py", line 110, in count
    return c()
  File "C:\Users\Administrator\AppData\Local\Programs\Python\Python310\lib\site-packages\django\db\models\query.py", line 620, in count
    return self.query.get_count(using=self.db)
  File "C:\Users\Administrator\AppData\Local\Programs\Python\Python310\lib\site-packages\django\db\models\sql\query.py", line 629, in get_count
    return obj.get_aggregation(using, {"__count": Count("*")})["__count"]
  File "C:\Users\Administrator\AppData\Local\Programs\Python\Python310\lib\site-packages\django\db\models\sql\query.py", line 615, in get_aggregation
    result = compiler.execute_sql(SINGLE)
  File "C:\Users\Administrator\AppData\Local\Programs\Python\Python310\lib\site-packages\django\db\models\sql\compiler.py", line 1562, in execute_sql
    cursor.execute(sql, params)
  File "C:\Users\Administrator\AppData\Local\Programs\Python\Python310\lib\site-packages\django\db\backends\utils.py", line 79, in execute
    return self._execute_with_wrappers(
  File "C:\Users\Administrator\AppData\Local\Programs\Python\Python310\lib\site-packages\django\db\backends\utils.py", line 92, in _execute_with_wrappers
    return executor(sql, params, many, context)
  File "C:\Users\Administrator\AppData\Local\Programs\Python\Python310\lib\site-packages\django\db\backends\utils.py", line 100, in _execute
    with self.db.wrap_database_errors:
  File "C:\Users\Administrator\AppData\Local\Programs\Python\Python310\lib\site-packages\django\db\utils.py", line 91, in __exit__
    raise dj_exc_value.with_traceback(traceback) from exc_value
  File "C:\Users\Administrator\AppData\Local\Programs\Python\Python310\lib\site-packages\django\db\backends\utils.py", line 105, in _execute
    return self.cursor.execute(sql, params)
  File "C:\Users\Administrator\AppData\Local\Programs\Python\Python310\lib\site-packages\django\db\backends\sqlite3\base.py", line 329, in execute
    return super().execute(query, params)
django.db.utils.OperationalError: no such table: myapp_laptop
"GET /admin/myapp/laptop/ HTTP/1.1" 500 145
